2024-02-09 18:51:50,736 - instabot version: 0.117.0 (bot) - INFO - Instabot version: 0.117.0 Started
2024-02-09 18:51:50,736 - instabot version: 0.117.0 (bot) - DEBUG - Bot imported from S:\Python\Thotscraper\lib\site-packages\instabot\bot\bot.py
2024-02-09 18:51:50,737 - instabot version: 0.117.0 (api_login) - INFO - Not yet logged in starting: PRE-LOGIN FLOW!
2024-02-09 18:51:50,946 - instabot version: 0.117.0 (api) - DEBUG - POST to endpoint: accounts/get_prefill_candidates/ returned response: <Response [429]>
2024-02-09 18:51:50,946 - instabot version: 0.117.0 (api) - DEBUG - Responsecode indicates error; response content: b'{"message":"Please wait a few minutes before you try again.","status":"fail"}'
2024-02-09 18:51:50,946 - instabot version: 0.117.0 (api) - ERROR - Request returns 429 error!
2024-02-09 18:51:51,292 - instabot version: 0.117.0 (api) - DEBUG - POST to endpoint: qe/sync/ returned response: <Response [200]>
2024-02-09 18:51:51,507 - instabot version: 0.117.0 (api) - DEBUG - POST to endpoint: launcher/sync/ returned response: <Response [200]>
2024-02-09 18:51:51,672 - instabot version: 0.117.0 (api) - DEBUG - POST to endpoint: accounts/contact_point_prefill/ returned response: <Response [200]>
2024-02-09 18:51:53,032 - instabot version: 0.117.0 (api) - DEBUG - POST to endpoint: accounts/login/ returned response: <Response [200]>
2024-02-09 18:51:53,032 - instabot version: 0.117.0 (api) - INFO - Logged-in successfully as 'py_test_bot'!
2024-02-09 18:51:53,032 - instabot version: 0.117.0 (api_login) - INFO - LOGIN FLOW! Just logged-in: True
